Workbook

Sheet Employee Master Table
A1: Employee ID | B1: Employee Name | C1: Signature | D1: Department | E1: Designation | F1: Date of Joining | G1: Bank Name | H1: Bank Account No. | I1: PAN | J1: PF Applicable | K1: ESI Applicable | L1: Status | P1: 46023
A2: EMP001 | B2: Aarav Sharma | C2: Aarav Sharma | D2: Engineering | E2: Software Engineer | F2: 45306 | G2: HDFC Bank | H2: 50100234561001 | I2: AAAAA1237A | J2: Yes | K2: Yes | L2: Active | P2: 46054
A3: EMP002 | B3: Riya Verma | C3: Riya Verma | D3: HR | E3: HR Executive | F3: 45361 | G3: ICICI Bank | H3: 00340123456702 | I3: BBBBB2345B | J3: Yes | K3: Yes | L3: Active | P3: 46082
A4: EMP003 | B4: Kunal Jain | C4: Kunal Jain | D4: Finance | E4: Accountant | F4: 45112 | G4: SBI | H4: 31245678903001 | I4: CCCCC3456C | J4: Yes | K4: Yes | L4: Active | P4: 46113
A5: EMP004 | B5: Ananya Singh | C5: Ananya Singh | D5: Marketing | E5: Marketing Executive | F5: 45708 | G5: Axis Bank | H5: 91201004567804 | I5: DDDDD0456D | J5: Yes | K5: Yes | L5: Active | P5: 46143
A6: EMP005 | B6: Rahul Mehta | C6: Rahul Mehta | D6: Engineering | E6: Data Analyst | F6: 45516 | G6: HDFC Bank | H6: 50100234561005 | I6: EEEEE5678E | J6: Yes | K6: Yes | L6: Active | P6: 46174
A7: EMP006 | B7: Priya Patel | C7: Priya Patel | D7: Operations | E7: Operations Executive | F7: 45187 | G7: SBI | H7: 31245678906006 | I7: FFFFF6789F | J7: Yes | K7: Yes | L7: Active | P7: 46204
A8: EMP007 | B8: Aditya Gupta | C8: Aditya Gupta | D8: Engineering | E8: ML Engineer | F8: 45659 | G8: ICICI Bank | H8: 00340123456707 | I8: GGGGG7098G | J8: Yes | K8: Yes | L8: Active | P8: 46235
A9: EMP008 | B9: Sneha Joshi | C9: Sneha Joshi | D9: Finance | E9: Financial Analyst | F9: 45407 | G9: Axis Bank | H9: 91201004567808 | I9: HHHHH8901H | J9: Yes | K9: Yes | L9: Active | P9: 46266
A10: EMP009 | B10: Mohit Verma | C10: Mohit Verma | D10: Sales | E10: Sales Executive | F10: 45454 | G10: HDFC Bank | H10: 50100234561009 | I10: JJJJJ9012J | J10: Yes | K10: Yes | L10: Active | P10: 46296
A11: EMP010 | B11: Neha Kapoor | C11: Neha Kapoor | D11: HR | E11: HR Manager | F11: 44873 | G11: SBI | H11: 31245678900010 | I11: KKKKK0123K | J11: Yes | K11: Yes | L11: Active | P11: 46327
P12: 46357

Sheet Salary Structure
A1: Employee ID | B1: Basic Salary | C1: HRA | D1: Conveyance | E1: Special Allowance
A2: ='Employee Master Table'!A2 -> EMP001 | B2: 30000 | C2: =B2*40/100 -> 12000 | D2: =B2*10/100 -> 3000 | E2: 5000
A3: ='Employee Master Table'!A3 -> EMP002 | B3: 25000 | C3: =B3*40/100 -> 10000 | D3: =B3*10/100 -> 2500 | E3: 4000
A4: ='Employee Master Table'!A4 -> EMP003 | B4: 28000 | C4: =B4*40/100 -> 11200 | D4: =B4*10/100 -> 2800 | E4: 4500
A5: ='Employee Master Table'!A5 -> EMP004 | B5: 26000 | C5: =B5*40/100 -> 10400 | D5: =B5*10/100 -> 2600 | E5: 4000
A6: ='Employee Master Table'!A6 -> EMP005 | B6: 32000 | C6: =B6*40/100 -> 12800 | D6: =B6*10/100 -> 3200 | E6: 5500
A7: ='Employee Master Table'!A7 -> EMP006 | B7: 24000 | C7: =B7*40/100 -> 9600 | D7: =B7*10/100 -> 2400 | E7: 3500
A8: ='Employee Master Table'!A8 -> EMP007 | B8: 40000 | C8: =B8*40/100 -> 16000 | D8: =B8*10/100 -> 4000 | E8: 7000
A9: ='Employee Master Table'!A9 -> EMP008 | B9: 30000 | C9: =B9*40/100 -> 12000 | D9: =B9*10/100 -> 3000 | E9: 5000
A10: ='Employee Master Table'!A10 -> EMP009 | B10: 23000 | C10: =B10*40/100 -> 9200 | D10: =B10*10/100 -> 2300 | E10: 3500
A11: ='Employee Master Table'!A11 -> EMP010 | B11: 45000 | C11: =B11*40/100 -> 18000 | D11: =B11*10/100 -> 4500 | E11: 8000

Sheet Employee data
A1: Employee ID | B1: Salary Month | C1: Working Days | D1: LOP Days | E1: Paid Days | F1: Basic Salary | G1: House Rent Allowance | H1: Conveyance Allowance | I1: Special Allowance | J1: Other Earnings | K1: Payable Basic | L1: Gross Earnings | M1: Provident Fund (PF) | N1: ESI | O1: Professional Tax | P1: TDS | Q1: Other Deductions | R1: Other Deduction Remark | S1: Total Deductions | T1: Net Salary
A2: EMP001 | B2: 46023 | C2: =DAY(EOMONTH(B2,0)) -> 31 | D2: 1 | E2: =C2-D2 -> 30 | F2: =_xlfn.XLOOKUP(A2,'Salary Structure'!A:A,'Salary Structure'!B:B,"NOT FOUND") -> 30000 | G2: =_xlfn.XLOOKUP(A2,'Salary Structure'!A:A,'Salary Structure'!C:C,"NOT FOUND")*E2/C2 -> 11612.903 | H2: =_xlfn.XLOOKUP(A2,'Salary Structure'!A:A,'Salary Structure'!D:D,"NOT FOUND")*E2/C2 -> 2903.2258 | I2: =_xlfn.XLOOKUP(A2,'Salary Structure'!A:A,'Salary Structure'!E:E,"NOT FOUND")*E2/C2 -> 4838.7097 | J2: 0 | K2: =ROUND(F2*E2/C2,0) -> 29032 | L2: =SUM(G2:K2) -> 48386.839 | M2: =F2*12/100 -> 3600 | N2: =L2*75/10000 -> 362.90129 | O2: 208 | P2: =L2*3/100 -> 1451.6052 | Q2: 0 | S2: =M2+N2+O2+P2+Q2 -> 5622.5065 | T2: =L2-S2 -> 42764.332
A3: EMP002 | B3: 46023 | C3: =DAY(EOMONTH(B3,0)) -> 31 | D3: 2 | E3: =C3-D3 -> 29 | F3: =_xlfn.XLOOKUP(A3,'Salary Structure'!A:A,'Salary Structure'!B:B,"NOT FOUND") -> 25000 | G3: =_xlfn.XLOOKUP(A3,'Salary Structure'!A:A,'Salary Structure'!C:C,"NOT FOUND")*E3/C3 -> 9354.8387 | H3: =_xlfn.XLOOKUP(A3,'Salary Structure'!A:A,'Salary Structure'!D:D,"NOT FOUND")*E3/C3 -> 2338.7097 | I3: =_xlfn.XLOOKUP(A3,'Salary Structure'!A:A,'Salary Structure'!E:E,"NOT FOUND")*E3/C3 -> 3741.9355 | J3: 0 | K3: =ROUND(F3*E3/C3,0) -> 23387 | L3: =SUM(G3:K3) -> 38822.484 | M3: =F3*12/100 -> 3000 | N3: =L3*75/10000 -> 291.16863 | O3: 208 | P3: =L3*3/100 -> 1164.6745 | Q3: 0 | S3: =M3+N3+O3+P3+Q3 -> 4663.8431 | T3: =L3-S3 -> 34158.641
A4: EMP003 | B4: 46023 | C4: =DAY(EOMONTH(B4,0)) -> 31 | D4: 1 | E4: =C4-D4 -> 30 | F4: =_xlfn.XLOOKUP(A4,'Salary Structure'!A:A,'Salary Structure'!B:B,"NOT FOUND") -> 28000 | G4: =_xlfn.XLOOKUP(A4,'Salary Structure'!A:A,'Salary Structure'!C:C,"NOT FOUND")*E4/C4 -> 10838.71 | H4: =_xlfn.XLOOKUP(A4,'Salary Structure'!A:A,'Salary Structure'!D:D,"NOT FOUND")*E4/C4 -> 2709.6774 | I4: =_xlfn.XLOOKUP(A4,'Salary Structure'!A:A,'Salary Structure'!E:E,"NOT FOUND")*E4/C4 -> 4354.8387 | J4: 0 | K4: =ROUND(F4*E4/C4,0) -> 27097 | L4: =SUM(G4:K4) -> 45000.226 | M4: =F4*12/100 -> 3360 | N4: =L4*75/10000 -> 337.50169 | O4: 208 | P4: =L4*3/100 -> 1350.0068 | Q4: 300 | R4: Loan/Advance EMI recovery | S4: =M4+N4+O4+P4+Q4 -> 5555.5085 | T4: =L4-S4 -> 39444.717
A5: EMP004 | B5: 46023 | C5: =DAY(EOMONTH(B5,0)) -> 31 | D5: 0 | E5: =C5-D5 -> 31 | F5: =_xlfn.XLOOKUP(A5,'Salary Structure'!A:A,'Salary Structure'!B:B,"NOT FOUND") -> 26000 | G5: =_xlfn.XLOOKUP(A5,'Salary Structure'!A:A,'Salary Structure'!C:C,"NOT FOUND")*E5/C5 -> 10400 | H5: =_xlfn.XLOOKUP(A5,'Salary Structure'!A:A,'Salary Structure'!D:D,"NOT FOUND")*E5/C5 -> 2600 | I5: =_xlfn.XLOOKUP(A5,'Salary Structure'!A:A,'Salary Structure'!E:E,"NOT FOUND")*E5/C5 -> 4000 | J5: 0 | K5: =ROUND(F5*E5/C5,0) -> 26000 | L5: =SUM(G5:K5) -> 43000 | M5: =F5*12/100 -> 3120 | N5: =L5*75/10000 -> 322.5 | O5: 208 | P5: =L5*3/100 -> 1290 | Q5: 0 | S5: =M5+N5+O5+P5+Q5 -> 4940.5 | T5: =L5-S5 -> 38059.5
A6: EMP005 | B6: 46023 | C6: =DAY(EOMONTH(B6,0)) -> 31 | D6: 2 | E6: =C6-D6 -> 29 | F6: =_xlfn.XLOOKUP(A6,'Salary Structure'!A:A,'Salary Structure'!B:B,"NOT FOUND") -> 32000 | G6: =_xlfn.XLOOKUP(A6,'Salary Structure'!A:A,'Salary Structure'!C:C,"NOT FOUND")*E6/C6 -> 11974.194 | H6: =_xlfn.XLOOKUP(A6,'Salary Structure'!A:A,'Salary Structure'!D:D,"NOT FOUND")*E6/C6 -> 2993.5484 | I6: =_xlfn.XLOOKUP(A6,'Salary Structure'!A:A,'Salary Structure'!E:E,"NOT FOUND")*E6/C6 -> 5145.1613 | J6: 0 | K6: =ROUND(F6*E6/C6,0) -> 29935 | L6: =SUM(G6:K6) -> 50047.903 | M6: =F6*12/100 -> 3840 | N6: =L6*75/10000 -> 375.35927 | O6: 208 | P6: =L6*3/100 -> 1501.4371 | Q6: 0 | S6: =M6+N6+O6+P6+Q6 -> 5924.7964 | T6: =L6-S6 -> 44123.107
A7: EMP006 | B7: 46023 | C7: =DAY(EOMONTH(B7,0)) -> 31 | D7: 1 | E7: =C7-D7 -> 30 | F7: =_xlfn.XLOOKUP(A7,'Salary Structure'!A:A,'Salary Structure'!B:B,"NOT FOUND") -> 24000 | G7: =_xlfn.XLOOKUP(A7,'Salary Structure'!A:A,'Salary Structure'!C:C,"NOT FOUND")*E7/C7 -> 9290.3226 | H7: =_xlfn.XLOOKUP(A7,'Salary Structure'!A:A,'Salary Structure'!D:D,"NOT FOUND")*E7/C7 -> 2322.5806 | I7: =_xlfn.XLOOKUP(A7,'Salary Structure'!A:A,'Salary Structure'!E:E,"NOT FOUND")*E7/C7 -> 3387.0968 | J7: 0 | K7: =ROUND(F7*E7/C7,0) -> 23226 | L7: =SUM(G7:K7) -> 38226 | M7: =F7*12/100 -> 2880 | N7: =L7*75/10000 -> 286.695 | O7: 208 | P7: =L7*3/100 -> 1146.78 | Q7: 0 | S7: =M7+N7+O7+P7+Q7 -> 4521.475 | T7: =L7-S7 -> 33704.525
A8: EMP007 | B8: 46023 | C8: =DAY(EOMONTH(B8,0)) -> 31 | D8: 2 | E8: =C8-D8 -> 29 | F8: =_xlfn.XLOOKUP(A8,'Salary Structure'!A:A,'Salary Structure'!B:B,"NOT FOUND") -> 40000 | G8: =_xlfn.XLOOKUP(A8,'Salary Structure'!A:A,'Salary Structure'!C:C,"NOT FOUND")*E8/C8 -> 14967.742 | H8: =_xlfn.XLOOKUP(A8,'Salary Structure'!A:A,'Salary Structure'!D:D,"NOT FOUND")*E8/C8 -> 3741.9355 | I8: =_xlfn.XLOOKUP(A8,'Salary Structure'!A:A,'Salary Structure'!E:E,"NOT FOUND")*E8/C8 -> 6548.3871 | J8: 0 | K8: =ROUND(F8*E8/C8,0) -> 37419 | L8: =SUM(G8:K8) -> 62677.065 | M8: =F8*12/100 -> 4800 | N8: =L8*75/10000 -> 470.07798 | O8: 208 | P8: =L8*3/100 -> 1880.3119 | Q8: 0 | S8: =M8+N8+O8+P8+Q8 -> 7358.3899 | T8: =L8-S8 -> 55318.675
A9: EMP008 | B9: 46023 | C9: =DAY(EOMONTH(B9,0)) -> 31 | D9: 0 | E9: =C9-D9 -> 31 | F9: =_xlfn.XLOOKUP(A9,'Salary Structure'!A:A,'Salary Structure'!B:B,"NOT FOUND") -> 30000 | G9: =_xlfn.XLOOKUP(A9,'Salary Structure'!A:A,'Salary Structure'!C:C,"NOT FOUND")*E9/C9 -> 12000 | H9: =_xlfn.XLOOKUP(A9,'Salary Structure'!A:A,'Salary Structure'!D:D,"NOT FOUND")*E9/C9 -> 3000 | I9: =_xlfn.XLOOKUP(A9,'Salary Structure'!A:A,'Salary Structure'!E:E,"NOT FOUND")*E9/C9 -> 5000 | J9: 0 | K9: =ROUND(F9*E9/C9,0) -> 30000 | L9: =SUM(G9:K9) -> 50000 | M9: =F9*12/100 -> 3600 | N9: =L9*75/10000 -> 375 | O9: 208 | P9: =L9*3/100 -> 1500 | Q9: 0 | S9: =M9+N9+O9+P9+Q9 -> 5683 | T9: =L9-S9 -> 44317
A10: EMP009 | B10: 46023 | C10: =DAY(EOMONTH(B10,0)) -> 31 | D10: 7 | E10: =C10-D10 -> 24 | F10: =_xlfn.XLOOKUP(A10,'Salary Structure'!A:A,'Salary Structure'!B:B,"NOT FOUND") -> 23000 | G10: =_xlfn.XLOOKUP(A10,'Salary Structure'!A:A,'Salary Structure'!C:C,"NOT FOUND")*E10/C10 -> 7122.5806 | H10: =_xlfn.XLOOKUP(A10,'Salary Structure'!A:A,'Salary Structure'!D:D,"NOT FOUND")*E10/C10 -> 1780.6452 | I10: =_xlfn.XLOOKUP(A10,'Salary Structure'!A:A,'Salary Structure'!E:E,"NOT FOUND")*E10/C10 -> 2709.6774 | J10: 0 | K10: =ROUND(F10*E10/C10,0) -> 17806 | L10: =SUM(G10:K10) -> 29418.903 | M10: =F10*12/100 -> 2760 | N10: =L10*75/10000 -> 220.64177 | O10: 167 | P10: =L10*3/100 -> 882.5671 | Q10: 0 | S10: =M10+N10+O10+P10+Q10 -> 4030.2089 | T10: =L10-S10 -> 25388.694
A11: EMP010 | B11: 46023 | C11: =DAY(EOMONTH(B11,0)) -> 31 | D11: 0 | E11: =C11-D11 -> 31 | F11: =_xlfn.XLOOKUP(A11,'Salary Structure'!A:A,'Salary Structure'!B:B,"NOT FOUND") -> 45000 | G11: =_xlfn.XLOOKUP(A11,'Salary Structure'!A:A,'Salary Structure'!C:C,"NOT FOUND")*E11/C11 -> 18000 | H11: =_xlfn.XLOOKUP(A11,'Salary Structure'!A:A,'Salary Structure'!D:D,"NOT FOUND")*E11/C11 -> 4500 | I11: =_xlfn.XLOOKUP(A11,'Salary Structure'!A:A,'Salary Structure'!E:E,"NOT FOUND")*E11/C11 -> 8000 | J11: 0 | K11: =ROUND(F11*E11/C11,0) -> 45000 | L11: =SUM(G11:K11) -> 75500 | M11: =F11*12/100 -> 5400 | N11: =L11*75/10000 -> 566.25 | O11: 208 | P11: =L11*3/100 -> 2265 | Q11: 500 | R11: Loan/Advance EMI recovery | S11: =M11+N11+O11+P11+Q11 -> 8939.25 | T11: =L11-S11 -> 66560.75
A12: EMP001 | B12: 46054 | C12: =DAY(EOMONTH(B12,0)) -> 28 | D12: 2 | E12: =C12-D12 -> 26 | F12: =_xlfn.XLOOKUP(A12,'Salary Structure'!A:A,'Salary Structure'!B:B,"NOT FOUND") -> 30000 | G12: =_xlfn.XLOOKUP(A12,'Salary Structure'!A:A,'Salary Structure'!C:C,"NOT FOUND")*E12/C12 -> 11142.857 | H12: =_xlfn.XLOOKUP(A12,'Salary Structure'!A:A,'Salary Structure'!D:D,"NOT FOUND")*E12/C12 -> 2785.7143 | I12: =_xlfn.XLOOKUP(A12,'Salary Structure'!A:A,'Salary Structure'!E:E,"NOT FOUND")*E12/C12 -> 4642.8571 | J12: 0 | K12: =ROUND(F12*E12/C12,0) -> 27857 | L12: =SUM(G12:K12) -> 46428.429 | M12: =F12*12/100 -> 3600 | N12: =L12*75/10000 -> 348.21321 | O12: 208 | P12: =L12*3/100 -> 1392.8529 | Q12: 0 | S12: =M12+N12+O12+P12+Q12 -> 5549.0661 | T12: =L12-S12 -> 40879.363
A13: EMP002 | B13: 46054 | C13: =DAY(EOMONTH(B13,0)) -> 28 | D13: 2 | E13: =C13-D13 -> 26 | F13: =_xlfn.XLOOKUP(A13,'Salary Structure'!A:A,'Salary Structure'!B:B,"NOT FOUND") -> 25000 | G13: =_xlfn.XLOOKUP(A13,'Salary Structure'!A:A,'Salary Structure'!C:C,"NOT FOUND")*E13/C13 -> 9285.7143 | H13: =_xlfn.XLOOKUP(A13,'Salary Structure'!A:A,'Salary Structure'!D:D,"NOT FOUND")*E13/C13 -> 2321.4286 | I13: =_xlfn.XLOOKUP(A13,'Salary Structure'!A:A,'Salary Structure'!E:E,"NOT FOUND")*E13/C13 -> 3714.2857 | J13: 0 | K13: =ROUND(F13*E13/C13,0) -> 23214 | L13: =SUM(G13:K13) -> 38535.429 | M13: =F13*12/100 -> 3000 | N13: =L13*75/10000 -> 289.01571 | O13: 208 | P13: =L13*3/100 -> 1156.0629 | Q13: 0 | S13: =M13+N13+O13+P13+Q13 -> 4653.0786 | T13: =L13-S13 -> 33882.35
A14: EMP003 | B14: 46054 | C14: =DAY(EOMONTH(B14,0)) -> 28 | D14: 6 | E14: =C14-D14 -> 22 | F14: =_xlfn.XLOOKUP(A14,'Salary Structure'!A:A,'Salary Structure'!B:B,"NOT FOUND") -> 28000 | G14: =_xlfn.XLOOKUP(A14,'Salary Structure'!A:A,'Salary Structure'!C:C,"NOT FOUND")*E14/C14 -> 8800 | H14: =_xlfn.XLOOKUP(A14,'Salary Structure'!A:A,'Salary Structure'!D:D,"NOT FOUND")*E14/C14 -> 2200 | I14: =_xlfn.XLOOKUP(A14,'Salary Structure'!A:A,'Salary Structure'!E:E,"NOT FOUND")*E14/C14 -> 3535.7143 | J14: 0 | K14: =ROUND(F14*E14/C14,0) -> 22000 | L14: =SUM(G14:K14) -> 36535.714 | M14: =F14*12/100 -> 3360 | N14: =L14*75/10000 -> 274.01786 | O14: 208 | P14: =L14*3/100 -> 1096.0714 | Q14: 300 | R14: Loan/Advance EMI recovery | S14: =M14+N14+O14+P14+Q14 -> 5238.0893 | T14: =L14-S14 -> 31297.625
A15: EMP004 | B15: 46054 | C15: =DAY(EOMONTH(B15,0)) -> 28 | D15: 2 | E15: =C15-D15 -> 26 | F15: =_xlfn.XLOOKUP(A15,'Salary Structure'!A:A,'Salary Structure'!B:B,"NOT FOUND") -> 26000 | G15: =_xlfn.XLOOKUP(A15,'Salary Structure'!A:A,'Salary Structure'!C:C,"NOT FOUND")*E15/C15 -> 9657.1429 | H15: =_xlfn.XLOOKUP(A15,'Salary Structure'!A:A,'Salary Structure'!D:D,"NOT FOUND")*E15/C15 -> 2414.2857 | I15: =_xlfn.XLOOKUP(A15,'Salary Structure'!A:A,'Salary Structure'!E:E,"NOT FOUND")*E15/C15 -> 3714.2857 | J15: 0 | K15: =ROUND(F15*E15/C15,0) -> 24143 | L15: =SUM(G15:K15) -> 39928.714 | M15: =F15*12/100 -> 3120 | N15: =L15*75/10000 -> 299.46536 | O15: 208 | P15: =L15*3/100 -> 1197.8614 | Q15: 0 | S15: =M15+N15+O15+P15+Q15 -> 4825.3268 | T15: =L15-S15 -> 35103.387
A16: EMP005 | B16: 46054 | C16: =DAY(EOMONTH(B16,0)) -> 28 | D16: 0 | E16: =C16-D16 -> 28 | F16: =_xlfn.XLOOKUP(A16,'Salary Structure'!A:A,'Salary Structure'!B:B,"NOT FOUND") -> 32000 | G16: =_xlfn.XLOOKUP(A16,'Salary Structure'!A:A,'Salary Structure'!C:C,"NOT FOUND")*E16/C16 -> 12800 | H16: =_xlfn.XLOOKUP(A16,'Salary Structure'!A:A,'Salary Structure'!D:D,"NOT FOUND")*E16/C16 -> 3200 | I16: =_xlfn.XLOOKUP(A16,'Salary Structure'!A:A,'Salary Structure'!E:E,"NOT FOUND")*E16/C16 -> 5500 | J16: 0 | K16: =ROUND(F16*E16/C16,0) -> 32000 | L16: =SUM(G16:K16) -> 53500 | M16: =F16*12/100 -> 3840 | N16: =L16*75/10000 -> 401.25 | O16: 208 | P16: =L16*3/100 -> 1605 | Q16: 0 | S16: =M16+N16+O16+P16+Q16 -> 6054.25 | T16: =L16-S16 -> 47445.75
A17: EMP006 | B17: 46054 | C17: =DAY(EOMONTH(B17,0)) -> 28 | D17: 2 | E17: =C17-D17 -> 26 | F17: =_xlfn.XLOOKUP(A17,'Salary Structure'!A:A,'Salary Structure'!B:B,"NOT FOUND") -> 24000 | G17: =_xlfn.XLOOKUP(A17,'Salary Structure'!A:A,'Salary Structure'!C:C,"NOT FOUND")*E17/C17 -> 8914.2857 | H17: =_xlfn.XLOOKUP(A17,'Salary Structure'!A:A,'Salary Structure'!D:D,"NOT FOUND")*E17/C17 -> 2228.5714 | I17: =_xlfn.XLOOKUP(A17,'Salary Structure'!A:A,'Salary Structure'!E:E,"NOT FOUND")*E17/C17 -> 3250 | J17: 0 | K17: =ROUND(F17*E17/C17,0) -> 22286 | L17: =SUM(G17:K17) -> 36678.857 | M17: =F17*12/100 -> 2880 | N17: =L17*75/10000 -> 275.09143 | O17: 208 | P17: =L17*3/100 -> 1100.3657 | Q17: 0 | S17: =M17+N17+O17+P17+Q17 -> 4463.4571 | T17: =L17-S17 -> 32215.4
A18: EMP007 | B18: 46054 | C18: =DAY(EOMONTH(B18,0)) -> 28 | D18: 0 | E18: =C18-D18 -> 28 | F18: =_xlfn.XLOOKUP(A18,'Salary Structure'!A:A,'Salary Structure'!B:B,"NOT FOUND") -> 40000 | G18: =_xlfn.XLOOKUP(A18,'Salary Structure'!A:A,'Salary Structure'!C:C,"NOT FOUND")*E18/C18 -> 16000 | H18: =_xlfn.XLOOKUP(A18,'Salary Structure'!A:A,'Salary Structure'!D:D,"NOT FOUND")*E18/C18 -> 4000 | I18: =_xlfn.XLOOKUP(A18,'Salary Structure'!A:A,'Salary Structure'!E:E,"NOT FOUND")*E18/C18 -> 7000 | J18: 0 | K18: =ROUND(F18*E18/C18,0) -> 40000 | L18: =SUM(G18:K18) -> 67000 | M18: =F18*12/100 -> 4800 | N18: =L18*75/10000 -> 502.5 | O18: 208 | P18: =L18*3/100 -> 2010 | Q18: 0 | S18: =M18+N18+O18+P18+Q18 -> 7520.5 | T18: =L18-S18 -> 59479.5
A19: EMP008 | B19: 46054 | C19: =DAY(EOMONTH(B19,0)) -> 28 | D19: 6 | E19: =C19-D19 -> 22 | F19: =_xlfn.XLOOKUP(A19,'Salary Structure'!A:A,'Salary Structure'!B:B,"NOT FOUND") -> 30000 | G19: =_xlfn.XLOOKUP(A19,'Salary Structure'!A:A,'Salary Structure'!C:C,"NOT FOUND")*E19/C19 -> 9428.5714 | H19: =_xlfn.XLOOKUP(A19,'Salary Structure'!A:A,'Salary Structure'!D:D,"NOT FOUND")*E19/C19 -> 2357.1429 | I19: =_xlfn.XLOOKUP(A19,'Salary Structure'!A:A,'Salary Structure'!E:E,"NOT FOUND")*E19/C19 -> 3928.5714 | J19: 0 | K19: =ROUND(F19*E19/C19,0) -> 23571 | L19: =SUM(G19:K19) -> 39285.286 | M19: =F19*12/100 -> 3600 | N19: =L19*75/10000 -> 294.63964 | O19: 208 | P19: =L19*3/100 -> 1178.5586 | Q19: 0 | S19: =M19+N19+O19+P19+Q19 -> 5281.1982 | T19: =L19-S19 -> 34004.087
A20: EMP009 | B20: 46054 | C20: =DAY(EOMONTH(B20,0)) -> 28 | D20: 4 | E20: =C20-D20 -> 24 | F20: =_xlfn.XLOOKUP(A20,'Salary Structure'!A:A,'Salary Structure'!B:B,"NOT FOUND") -> 23000 | G20: =_xlfn.XLOOKUP(A20,'Salary Structure'!A:A,'Salary Structure'!C:C,"NOT FOUND")*E20/C20 -> 7885.7143 | H20: =_xlfn.XLOOKUP(A20,'Salary Structure'!A:A,'Salary Structure'!D:D,"NOT FOUND")*E20/C20 -> 1971.4286 | I20: =_xlfn.XLOOKUP(A20,'Salary Structure'!A:A,'Salary Structure'!E:E,"NOT FOUND")*E20/C20 -> 3000 | J20: 0 | K20: =ROUND(F20*E20/C20,0) -> 19714 | L20: =SUM(G20:K20) -> 32571.143 | M20: =F20*12/100 -> 2760 | N20: =L20*75/10000 -> 244.28357 | O20: 208 | P20: =L20*3/100 -> 977.13429 | Q20: 0 | S20: =M20+N20+O20+P20+Q20 -> 4189.4179 | T20: =L20-S20 -> 28381.725
A21: EMP010 | B21: 46054 | C21: =DAY(EOMONTH(B21,0)) -> 28 | D21: 1 | E21: =C21-D21 -> 27 | F21: =_xlfn.XLOOKUP(A21,'Salary Structure'!A:A,'Salary Structure'!B:B,"NOT FOUND") -> 45000 | G21: =_xlfn.XLOOKUP(A21,'Salary Structure'!A:A,'Salary Structure'!C:C,"NOT FOUND")*E21/C21 -> 17357.143 | H21: =_xlfn.XLOOKUP(A21,'Salary Structure'!A:A,'Salary Structure'!D:D,"NOT FOUND")*E21/C21 -> 4339.2857 | I21: =_xlfn.XLOOKUP(A21,'Salary Structure'!A:A,'Salary Structure'!E:E,"NOT FOUND")*E21/C21 -> 7714.2857 | J21: 1500 | K21: =ROUND(F21*E21/C21,0) -> 43393 | L21: =SUM(G21:K21) -> 74303.714 | M21: =F21*12/100 -> 5400 | N21: =L21*75/10000 -> 557.27786 | O21: 208 | P21: =L21*3/100 -> 2229.1114 | Q21: 500 | R21: Loan/Advance EMI recovery | S21: =M21+N21+O21+P21+Q21 -> 8894.3893 | T21: =L21-S21 -> 65409.325
A22: EMP001 | B22: 46082 | C22: =DAY(EOMONTH(B22,0)) -> 31 | D22: 0 | E22: =C22-D22 -> 31 | F22: =_xlfn.XLOOKUP(A22,'Salary Structure'!A:A,'Salary Structure'!B:B,"NOT FOUND") -> 30000 | G22: =_xlfn.XLOOKUP(A22,'Salary Structure'!A:A,'Salary Structure'!C:C,"NOT FOUND")*E22/C22 -> 12000 | H22: =_xlfn.XLOOKUP(A22,'Salary Structure'!A:A,'Salary Structure'!D:D,"NOT FOUND")*E22/C22 -> 3000 | I22: =_xlfn.XLOOKUP(A22,'Salary Structure'!A:A,'Salary Structure'!E:E,"NOT FOUND")*E22/C22 -> 5000 | J22: 0 | K22: =ROUND(F22*E22/C22,0) -> 30000 | L22: =SUM(G22:K22) -> 50000 | M22: =F22*12/100 -> 3600 | N22: =L22*75/10000 -> 375 | O22: 212 | P22: =L22*3/100 -> 1500 | Q22: 0 | S22: =M22+N22+O22+P22+Q22 -> 5687 | T22: =L22-S22 -> 44313
A23: EMP002 | B23: 46082 | C23: =DAY(EOMONTH(B23,0)) -> 31 | D23: 2 | E23: =C23-D23 -> 29 | F23: =_xlfn.XLOOKUP(A23,'Salary Structure'!A:A,'Salary Structure'!B:B,"NOT FOUND") -> 25000 | G23: =_xlfn.XLOOKUP(A23,'Salary Structure'!A:A,'Salary Structure'!C:C,"NOT FOUND")*E23/C23 -> 9354.8387 | H23: =_xlfn.XLOOKUP(A23,'Salary Structure'!A:A,'Salary Structure'!D:D,"NOT FOUND")*E23/C23 -> 2338.7097 | I23: =_xlfn.XLOOKUP(A23,'Salary Structure'!A:A,'Salary Structure'!E:E,"NOT FOUND")*E23/C23 -> 3741.9355 | J23: 0 | K23: =ROUND(F23*E23/C23,0) -> 23387 | L23: =SUM(G23:K23) -> 38822.484 | M23: =F23*12/100 -> 3000 | N23: =L23*75/10000 -> 291.16863 | O23: 212 | P23: =L23*3/100 -> 1164.6745 | Q23: 0 | S23: =M23+N23+O23+P23+Q23 -> 4667.8431 | T23: =L23-S23 -> 34154.641
A24: EMP003 | B24: 46082 | C24: =DAY(EOMONTH(B24,0)) -> 31 | D24: 0 | E24: =C24-D24 -> 31 | F24: =_xlfn.XLOOKUP(A24,'Salary Structure'!A:A,'Salary Structure'!B:B,"NOT FOUND") -> 28000 | G24: =_xlfn.XLOOKUP(A24,'Salary Structure'!A:A,'Salary Structure'!C:C,"NOT FOUND")*E24/C24 -> 11200 | H24: =_xlfn.XLOOKUP(A24,'Salary Structure'!A:A,'Salary Structure'!D:D,"NOT FOUND")*E24/C24 -> 2800 | I24: =_xlfn.XLOOKUP(A24,'Salary Structure'!A:A,'Salary Structure'!E:E,"NOT FOUND")*E24/C24 -> 4500 | J24: 0 | K24: =ROUND(F24*E24/C24,0) -> 28000 | L24: =SUM(G24:K24) -> 46500 | M24: =F24*12/100 -> 3360 | N24: =L24*75/10000 -> 348.75 | O24: 212 | P24: =L24*3/100 -> 1395 | Q24: 300 | R24: Loan/Advance EMI recovery | S24: =M24+N24+O24+P24+Q24 -> 5615.75 | T24: =L24-S24 -> 40884.25
A25: EMP004 | B25: 46082 | C25: =DAY(EOMONTH(B25,0)) -> 31 | D25: 0 | E25: =C25-D25 -> 31 | F25: =_xlfn.XLOOKUP(A25,'Salary Structure'!A:A,'Salary Structure'!B:B,"NOT FOUND") -> 26000 | G25: =_xlfn.XLOOKUP(A25,'Salary Structure'!A:A,'Salary Structure'!C:C,"NOT FOUND")*E25/C25 -> 10400 | H25: =_xlfn.XLOOKUP(A25,'Salary Structure'!A:A,'Salary Structure'!D:D,"NOT FOUND")*E25/C25 -> 2600 | I25: =_xlfn.XLOOKUP(A25,'Salary Structure'!A:A,'Salary Structure'!E:E,"NOT FOUND")*E25/C25 -> 4000 | J25: 0 | K25: =ROUND(F25*E25/C25,0) -> 26000 | L25: =SUM(G25:K25) -> 43000 | M25: =F25*12/100 -> 3120 | N25: =L25*75/10000 -> 322.5 | O25: 212 | P25: =L25*3/100 -> 1290 | Q25: 0 | S25: =M25+N25+O25+P25+Q25 -> 4944.5 | T25: =L25-S25 -> 38055.5
A26: EMP005 | B26: 46082 | C26: =DAY(EOMONTH(B26,0)) -> 31 | D26: 7 | E26: =C26-D26 -> 24 | F26: =_xlfn.XLOOKUP(A26,'Salary Structure'!A:A,'Salary Structure'!B:B,"NOT FOUND") -> 32000 | G26: =_xlfn.XLOOKUP(A26,'Salary Structure'!A:A,'Salary Structure'!C:C,"NOT FOUND")*E26/C26 -> 9909.6774 | H26: =_xlfn.XLOOKUP(A26,'Salary Structure'!A:A,'Salary Structure'!D:D,"NOT FOUND")*E26/C26 -> 2477.4194 | I26: =_xlfn.XLOOKUP(A26,'Salary Structure'!A:A,'Salary Structure'!E:E,"NOT FOUND")*E26/C26 -> 4258.0645 | J26: 0 | K26: =ROUND(F26*E26/C26,0) -> 24774 | L26: =SUM(G26:K26) -> 41419.161 | M26: =F26*12/100 -> 3840 | N26: =L26*75/10000 -> 310.64371 | O26: 212 | P26: =L26*3/100 -> 1242.5748 | Q26: 0 | S26: =M26+N26+O26+P26+Q26 -> 5605.2185 | T26: =L26-S26 -> 35813.943
A27: EMP006 | B27: 46082 | C27: =DAY(EOMONTH(B27,0)) -> 31 | D27: 0 | E27: =C27-D27 -> 31 | F27: =_xlfn.XLOOKUP(A27,'Salary Structure'!A:A,'Salary Structure'!B:B,"NOT FOUND") -> 24000 | G27: =_xlfn.XLOOKUP(A27,'Salary Structure'!A:A,'Salary Structure'!C:C,"NOT FOUND")*E27/C27 -> 9600 | H27: =_xlfn.XLOOKUP(A27,'Salary Structure'!A:A,'Salary Structure'!D:D,"NOT FOUND")*E27/C27 -> 2400 | I27: =_xlfn.XLOOKUP(A27,'Salary Structure'!A:A,'Salary Structure'!E:E,"NOT FOUND")*E27/C27 -> 3500 | J27: 0 | K27: =ROUND(F27*E27/C27,0) -> 24000 | L27: =SUM(G27:K27) -> 39500 | M27: =F27*12/100 -> 2880 | N27: =L27*75/10000 -> 296.25 | O27: 212 | P27: =L27*3/100 -> 1185 | Q27: 0 | S27: =M27+N27+O27+P27+Q27 -> 4573.25 | T27: =L27-S27 -> 34926.75
A28: EMP007 | B28: 46082 | C28: =DAY(EOMONTH(B28,0)) -> 31 | D28: 4 | E28: =C28-D28 -> 27 | F28: =_xlfn.XLOOKUP(A28,'Salary Structure'!A:A,'Salary Structure'!B:B,"NOT FOUND") -> 40000 | G28: =_xlfn.XLOOKUP(A28,'Salary Structure'!A:A,'Salary Structure'!C:C,"NOT FOUND")*E28/C28 -> 13935.484 | H28: =_xlfn.XLOOKUP(A28,'Salary Structure'!A:A,'Salary Structure'!D:D,"NOT FOUND")*E28/C28 -> 3483.871 | I28: =_xlfn.XLOOKUP(A28,'Salary Structure'!A:A,'Salary Structure'!E:E,"NOT FOUND")*E28/C28 -> 6096.7742 | J28: 0 | K28: =ROUND(F28*E28/C28,0) -> 34839 | L28: =SUM(G28:K28) -> 58355.129 | M28: =F28*12/100 -> 4800 | N28: =L28*75/10000 -> 437.66347 | O28: 212 | P28: =L28*3/100 -> 1750.6539 | Q28: 0 | S28: =M28+N28+O28+P28+Q28 -> 7200.3173 | T28: =L28-S28 -> 51154.812
A29: EMP008 | B29: 46082 | C29: =DAY(EOMONTH(B29,0)) -> 31 | D29: 0 | E29: =C29-D29 -> 31 | F29: =_xlfn.XLOOKUP(A29,'Salary Structure'!A:A,'Salary Structure'!B:B,"NOT FOUND") -> 30000 | G29: =_xlfn.XLOOKUP(A29,'Salary Structure'!A:A,'Salary Structure'!C:C,"NOT FOUND")*E29/C29 -> 12000 | H29: =_xlfn.XLOOKUP(A29,'Salary Structure'!A:A,'Salary Structure'!D:D,"NOT FOUND")*E29/C29 -> 3000 | I29: =_xlfn.XLOOKUP(A29,'Salary Structure'!A:A,'Salary Structure'!E:E,"NOT FOUND")*E29/C29 -> 5000 | J29: 0 | K29: =ROUND(F29*E29/C29,0) -> 30000 | L29: =SUM(G29:K29) -> 50000 | M29: =F29*12/100 -> 3600 | N29: =L29*75/10000 -> 375 | O29: 212 | P29: =L29*3/100 -> 1500 | Q29: 0 | S29: =M29+N29+O29+P29+Q29 -> 5687 | T29: =L29-S29 -> 44313
A30: EMP009 | B30: 46082 | C30: =DAY(EOMONTH(B30,0)) -> 31 | D30: 0 | E30: =C30-D30 -> 31 | F30: =_xlfn.XLOOKUP(A30,'Salary Structure'!A:A,'Salary Structure'!B:B,"NOT FOUND") -> 23000 | G30: =_xlfn.XLOOKUP(A30,'Salary Structure'!A:A,'Salary Structure'!C:C,"NOT FOUND")*E30/C30 -> 9200 | H30: =_xlfn.XLOOKUP(A30,'Salary Structure'!A:A,'Salary Structure'!D:D,"NOT FOUND")*E30/C30 -> 2300 | I30: =_xlfn.XLOOKUP(A30,'Salary Structure'!A:A,'Salary Structure'!E:E,"NOT FOUND")*E30/C30 -> 3500 | J30: 0 | K30: =ROUND(F30*E30/C30,0) -> 23000 | L30: =SUM(G30:K30) -> 38000 | M30: =F30*12/100 -> 2760 | N30: =L30*75/10000 -> 285 | O30: 212 | P30: =L30*3/100 -> 1140 | Q30: 0 | S30: =M30+N30+O30+P30+Q30 -> 4397 | T30: =L30-S30 -> 33603
A31: EMP010 | B31: 46082 | C31: =DAY(EOMONTH(B31,0)) -> 31 | D31: 0 | E31: =C31-D31 -> 31 | F31: =_xlfn.XLOOKUP(A31,'Salary Structure'!A:A,'Salary Structure'!B:B,"NOT FOUND") -> 45000 | G31: =_xlfn.XLOOKUP(A31,'Salary Structure'!A:A,'Salary Structure'!C:C,"NOT FOUND")*E31/C31 -> 18000 | H31: =_xlfn.XLOOKUP(A31,'Salary Structure'!A:A,'Salary Structure'!D:D,"NOT FOUND")*E31/C31 -> 4500 | I31: =_xlfn.XLOOKUP(A31,'Salary Structure'!A:A,'Salary Structure'!E:E,"NOT FOUND")*E31/C31 -> 8000 | J31: 0 | K31: =ROUND(F31*E31/C31,0) -> 45000 | L31: =SUM(G31:K31) -> 75500 | M31: =F31*12/100 -> 5400 | N31: =L31*75/10000 -> 566.25 | O31: 212 | P31: =L31*3/100 -> 2265 | Q31: 500 | R31: Loan/Advance EMI recovery | S31: =M31+N31+O31+P31+Q31 -> 8943.25 | T31: =L31-S31 -> 66556.75
A32: EMP001 | B32: 46113 | C32: =DAY(EOMONTH(B32,0)) -> 30 | D32: 4 | E32: =C32-D32 -> 26 | F32: =_xlfn.XLOOKUP(A32,'Salary Structure'!A:A,'Salary Structure'!B:B,"NOT FOUND") -> 30000 | G32: =_xlfn.XLOOKUP(A32,'Salary Structure'!A:A,'Salary Structure'!C:C,"NOT FOUND")*E32/C32 -> 10400 | H32: =_xlfn.XLOOKUP(A32,'Salary Structure'!A:A,'Salary Structure'!D:D,"NOT FOUND")*E32/C32 -> 2600 | I32: =_xlfn.XLOOKUP(A32,'Salary Structure'!A:A,'Salary Structure'!E:E,"NOT FOUND")*E32/C32 -> 4333.3333 | J32: 0 | K32: =ROUND(F32*E32/C32,0) -> 26000 | L32: =SUM(G32:K32) -> 43333.333 | M32: =F32*12/100 -> 3600 | N32: =L32*75/10000 -> 325 | O32: 208 | P32: =L32*3/100 -> 1300 | Q32: 0 | S32: =M32+N32+O32+P32+Q32 -> 5433 | T32: =L32-S32 -> 37900.333
A33: EMP002 | B33: 46113 | C33: =DAY(EOMONTH(B33,0)) -> 30 | D33: 3 | E33: =C33-D33 -> 27 | F33: =_xlfn.XLOOKUP(A33,'Salary Structure'!A:A,'Salary Structure'!B:B,"NOT FOUND") -> 25000 | G33: =_xlfn.XLOOKUP(A33,'Salary Structure'!A:A,'Salary Structure'!C:C,"NOT FOUND")*E33/C33 -> 9000 | H33: =_xlfn.XLOOKUP(A33,'Salary Structure'!A:A,'Salary Structure'!D:D,"NOT FOUND")*E33/C33 -> 2250 | I33: =_xlfn.XLOOKUP(A33,'Salary Structure'!A:A,'Salary Structure'!E:E,"NOT FOUND")*E33/C33 -> 3600 | J33: 0 | K33: =ROUND(F33*E33/C33,0) -> 22500 | L33: =SUM(G33:K33) -> 37350 | M33: =F33*12/100 -> 3000 | N33: =L33*75/10000 -> 280.125 | O33: 208 | P33: =L33*3/100 -> 1120.5 | Q33: 0 | S33: =M33+N33+O33+P33+Q33 -> 4608.625 | T33: =L33-S33 -> 32741.375
A34: EMP003 | B34: 46113 | C34: =DAY(EOMONTH(B34,0)) -> 30 | D34: 0 | E34: =C34-D34 -> 30 | F34: =_xlfn.XLOOKUP(A34,'Salary Structure'!A:A,'Salary Structure'!B:B,"NOT FOUND") -> 28000 | G34: =_xlfn.XLOOKUP(A34,'Salary Structure'!A:A,'Salary Structure'!C:C,"NOT FOUND")*E34/C34 -> 11200 | H34: =_xlfn.XLOOKUP(A34,'Salary Structure'!A:A,'Salary Structure'!D:D,"NOT FOUND")*E34/C34 -> 2800 | I34: =_xlfn.XLOOKUP(A34,'Salary Structure'!A:A,'Salary Structure'!E:E,"NOT FOUND")*E34/C34 -> 4500 | J34: 0 | K34: =ROUND(F34*E34/C34,0) -> 28000 | L34: =SUM(G34:K34) -> 46500 | M34: =F34*12/100 -> 3360 | N34: =L34*75/10000 -> 348.75 | O34: 208 | P34: =L34*3/100 -> 1395 | Q34: 300 | R34: Loan/Advance EMI recovery | S34: =M34+N34+O34+P34+Q34 -> 5611.75 | T34: =L34-S34 -> 40888.25
A35: EMP004 | B35: 46113 | C35: =DAY(EOMONTH(B35,0)) -> 30 | D35: 2 | E35: =C35-D35 -> 28 | F35: =_xlfn.XLOOKUP(A35,'Salary Structure'!A:A,'Salary Structure'!B:B,"NOT FOUND") -> 26000 | G35: =_xlfn.XLOOKUP(A35,'Salary Structure'!A:A,'Salary Structure'!C:C,"NOT FOUND")*E35/C35 -> 9706.6667 | H35: =_xlfn.XLOOKUP(A35,'Salary Structure'!A:A,'Salary Structure'!D:D,"NOT FOUND")*E35/C35 -> 2426.6667 | I35: =_xlfn.XLOOKUP(A35,'Salary Structure'!A:A,'Salary Structure'!E:E,"NOT FOUND")*E35/C35 -> 3733.3333 | J35: 0 | K35: =ROUND(F35*E35/C35,0) -> 24267 | L35: =SUM(G35:K35) -> 40133.667 | M35: =F35*12/100 -> 3120 | N35: =L35*75/10000 -> 301.0025 | O35: 208 | P35: =L35*3/100 -> 1204.01 | Q35: 0 | S35: =M35+N35+O35+P35+Q35 -> 4833.0125 | T35: =L35-S35 -> 35300.654
A36: EMP005 | B36: 46113 | C36: =DAY(EOMONTH(B36,0)) -> 30 | D36: 3 | E36: =C36-D36 -> 27 | F36: =_xlfn.XLOOKUP(A36,'Salary Structure'!A:A,'Salary Structure'!B:B,"NOT FOUND") -> 32000 | G36: =_xlfn.XLOOKUP(A36,'Salary Structure'!A:A,'Salary Structure'!C:C,"NOT FOUND")*E36/C36 -> 11520 | H36: =_xlfn.XLOOKUP(A36,'Salary Structure'!A:A,'Salary Structure'!D:D,"NOT FOUND")*E36/C36 -> 2880 | I36: =_xlfn.XLOOKUP(A36,'Salary Structure'!A:A,'Salary Structure'!E:E,"NOT FOUND")*E36/C36 -> 4950 | J36: 2000 | K36: =ROUND(F36*E36/C36,0) -> 28800 | L36: =SUM(G36:K36) -> 50150 | M36: =F36*12/100 -> 3840 | N36: =L36*75/10000 -> 376.125 | O36: 208 | P36: =L36*3/100 -> 1504.5 | Q36: 0 | S36: =M36+N36+O36+P36+Q36 -> 5928.625 | T36: =L36-S36 -> 44221.375
A37: EMP006 | B37: 46113 | C37: =DAY(EOMONTH(B37,0)) -> 30 | D37: 0 | E37: =C37-D37 -> 30 | F37: =_xlfn.XLOOKUP(A37,'Salary Structure'!A:A,'Salary Structure'!B:B,"NOT FOUND") -> 24000 | G37: =_xlfn.XLOOKUP(A37,'Salary Structure'!A:A,'Salary Structure'!C:C,"NOT FOUND")*E37/C37 -> 9600 | H37: =_xlfn.XLOOKUP(A37,'Salary Structure'!A:A,'Salary Structure'!D:D,"NOT FOUND")*E37/C37 -> 2400 | I37: =_xlfn.XLOOKUP(A37,'Salary Structure'!A:A,'Salary Structure'!E:E,"NOT FOUND")*E37/C37 -> 3500 | J37: 0 | K37: =ROUND(F37*E37/C37,0) -> 24000 | L37: =SUM(G37:K37) -> 39500 | M37: =F37*12/100 -> 2880 | N37: =L37*75/10000 -> 296.25 | O37: 208 | P37: =L37*3/100 -> 1185 | Q37: 0 | S37: =M37+N37+O37+P37+Q37 -> 4569.25 | T37: =L37-S37 -> 34930.75
A38: EMP007 | B38: 46113 | C38: =DAY(EOMONTH(B38,0)) -> 30 | D38: 0 | E38: =C38-D38 -> 30 | F38: =_xlfn.XLOOKUP(A38,'Salary Structure'!A:A,'Salary Structure'!B:B,"NOT FOUND") -> 40000 | G38: =_xlfn.XLOOKUP(A38,'Salary Structure'!A:A,'Salary Structure'!C:C,"NOT FOUND")*E38/C38 -> 16000 | H38: =_xlfn.XLOOKUP(A38,'Salary Structure'!A:A,'Salary Structure'!D:D,"NOT FOUND")*E38/C38 -> 4000 | I38: =_xlfn.XLOOKUP(A38,'Salary Structure'!A:A,'Salary Structure'!E:E,"NOT FOUND")*E38/C38 -> 7000 | J38: 0 | K38: =ROUND(F38*E38/C38,0) -> 40000 | L38: =SUM(G38:K38) -> 67000 | M38: =F38*12/100 -> 4800 | N38: =L38*75/10000 -> 502.5 | O38: 208 | P38: =L38*3/100 -> 2010 | Q38: 0 | S38: =M38+N38+O38+P38+Q38 -> 7520.5 | T38: =L38-S38 -> 59479.5
A39: EMP008 | B39: 46113 | C39: =DAY(EOMONTH(B39,0)) -> 30 | D39: 0 | E39: =C39-D39 -> 30 | F39: =_xlfn.XLOOKUP(A39,'Salary Structure'!A:A,'Salary Structure'!B:B,"NOT FOUND") -> 30000 | G39: =_xlfn.XLOOKUP(A39,'Salary Structure'!A:A,'Salary Structure'!C:C,"NOT FOUND")*E39/C39 -> 12000 | H39: =_xlfn.XLOOKUP(A39,'Salary Structure'!A:A,'Salary Structure'!D:D,"NOT FOUND")*E39/C39 -> 3000 | I39: =_xlfn.XLOOKUP(A39,'Salary Structure'!A:A,'Salary Structure'!E:E,"NOT FOUND")*E39/C39 -> 5000 | J39: 0 | K39: =ROUND(F39*E39/C39,0) -> 30000 | L39: =SUM(G39:K39) -> 50000 | M39: =F39*12/100 -> 3600 | N39: =L39*75/10000 -> 375 | O39: 208 | P39: =L39*3/100 -> 1500 | Q39: 0 | S39: =M39+N39+O39+P39+Q39 -> 5683 | T39: =L39-S39 -> 44317
A40: EMP009 | B40: 46113 | C40: =DAY(EOMONTH(B40,0)) -> 30 | D40: 2 | E40: =C40-D40 -> 28 | F40: =_xlfn.XLOOKUP(A40,'Salary Structure'!A:A,'Salary Structure'!B:B,"NOT FOUND") -> 23000 | G40: =_xlfn.XLOOKUP(A40,'Salary Structure'!A:A,'Salary Structure'!C:C,"NOT FOUND")*E40/C40 -> 8586.6667 | H40: =_xlfn.XLOOKUP(A40,'Salary Structure'!A:A,'Salary Structure'!D:D,"NOT FOUND")*E40/C40 -> 2146.6667 | I40: =_xlfn.XLOOKUP(A40,'Salary Structure'!A:A,'Salary Structure'!E:E,"NOT FOUND")*E40/C40 -> 3266.6667 | J40: 0 | K40: =ROUND(F40*E40/C40,0) -> 21467 | L40: =SUM(G40:K40) -> 35467 | M40: =F40*12/100 -> 2760 | N40: =L40*75/10000 -> 266.0025 | O40: 208 | P40: =L40*3/100 -> 1064.01 | Q40: 0 | S40: =M40+N40+O40+P40+Q40 -> 4298.0125 | T40: =L40-S40 -> 31168.987
...

Sheet Salary Slip
A1: Stark Industries
A3: Indore, Madhya Pradesh | hr@stark.example | +91 90231 10213
A5: SALARY SLIP
A7: Employee ID | B7: EMP005 | F7: Salary Month | G7: 46266
A11: EMPLOYEE DETAILS | F11: ATTENDANCE
A12: Employee Name | C12: =_xlfn.XLOOKUP('Salary Slip'!B7,'Employee Master Table'!A:A,'Employee Master Table'!B:B,"NOTFOUND") -> Rahul Mehta | F12: Salary Month | H12: {=VLOOKUP($B$7,_xlfn._xlws.FILTER('Employee data'!$A$1:$T$121,'Employee data'!$B$1:$B$121='Salary Slip'!$G$7),MATCH(F12,'Employee data'!$1:$1,0),0)} -> 46266
A13: Department | C13: =_xlfn.XLOOKUP('Salary Slip'!B7,'Employee Master Table'!A:A,'Employee Master Table'!D:D,"NOTFOUND") -> Engineering | F13: Working Days | H13: {=VLOOKUP($B$7,_xlfn._xlws.FILTER('Employee data'!$A$1:$T$121,'Employee data'!$B$1:$B$121='Salary Slip'!$G$7),MATCH(F13,'Employee data'!$1:$1,0),0)} -> 30
A14: Designation | C14: =_xlfn.XLOOKUP('Salary Slip'!B7,'Employee Master Table'!A:A,'Employee Master Table'!E:E,"NOTFOUND") -> Data Analyst | F14: LOP Days | H14: {=VLOOKUP($B$7,_xlfn._xlws.FILTER('Employee data'!$A$1:$T$121,'Employee data'!$B$1:$B$121='Salary Slip'!$G$7),MATCH(F14,'Employee data'!$1:$1,0),0)} -> 4
A15: Date of Joining | C15: =_xlfn.XLOOKUP('Salary Slip'!B7,'Employee Master Table'!A:A,'Employee Master Table'!F:F,"NOTFOUND") -> 45516 | F15: Paid Days | H15: {=VLOOKUP($B$7,_xlfn._xlws.FILTER('Employee data'!$A$1:$T$121,'Employee data'!$B$1:$B$121='Salary Slip'!$G$7),MATCH(F15,'Employee data'!$1:$1,0),0)} -> 26
A16: Bank Name | C16: =_xlfn.XLOOKUP('Salary Slip'!B7,'Employee Master Table'!A:A,'Employee Master Table'!G:G,"NOTFOUND") -> HDFC Bank
A17: Bank Account No. | C17: =LEFT(_xlfn.XLOOKUP('Salary Slip'!B7,'Employee Master Table'!A:A,'Employee Master Table'!H:H,"NOTFOUND"),3)&"********"&RIGHT(_xlfn.XLOOKUP('Salary Slip'!B7,'Employee Master Table'!A:A,'Employee Master Table'!H:H,"NOTFOUND"),3) -> 501********005
A18: PAN | C18: =LEFT(_xlfn.XLOOKUP('Salary Slip'!B7,'Employee Master Table'!A:A,'Employee Master Table'!I:I,"NOTFOUND"),2)&"******"&RIGHT(_xlfn.XLOOKUP('Salary Slip'!B7,'Employee Master Table'!A:A,'Employee Master Table'!I:I,"NOTFOUND"),2) -> EE******8E
A19: Status | C19: =_xlfn.XLOOKUP('Salary Slip'!B7,'Employee Master Table'!A:A,'Employee Master Table'!L:L,"NOTFOUND") -> Active
A21: EARNINGS | F21: DEDUCTIONS
A22: Basic Salary | D22: {=VLOOKUP($B$7,_xlfn._xlws.FILTER('Employee data'!$A$1:$T$121,'Employee data'!$B$1:$B$121='Salary Slip'!$G$7),MATCH(A22,'Employee data'!$1:$1,0),0)} -> 32000 | F22: Provident Fund (PF) | H22: {=VLOOKUP($B$7,_xlfn._xlws.FILTER('Employee data'!$A$1:$T$121,'Employee data'!$B$1:$B$121='Salary Slip'!$G$7),MATCH(F22,'Employee data'!$1:$1,0),0)} -> 3840
A23: House Rent Allowance | D23: {=VLOOKUP($B$7,_xlfn._xlws.FILTER('Employee data'!$A$1:$T$121,'Employee data'!$B$1:$B$121='Salary Slip'!$G$7),MATCH(A23,'Employee data'!$1:$1,0),0)} -> 11093.333 | F23: ESI | H23: {=VLOOKUP($B$7,_xlfn._xlws.FILTER('Employee data'!$A$1:$T$121,'Employee data'!$B$1:$B$121='Salary Slip'!$G$7),MATCH(F23,'Employee data'!$1:$1,0),0)} -> 347.7475
A24: Conveyance Allowance | D24: {=VLOOKUP($B$7,_xlfn._xlws.FILTER('Employee data'!$A$1:$T$121,'Employee data'!$B$1:$B$121='Salary Slip'!$G$7),MATCH(A24,'Employee data'!$1:$1,0),0)} -> 2773.3333 | F24: Professional Tax | H24: {=VLOOKUP($B$7,_xlfn._xlws.FILTER('Employee data'!$A$1:$T$121,'Employee data'!$B$1:$B$121='Salary Slip'!$G$7),MATCH(F24,'Employee data'!$1:$1,0),0)} -> 208
A25: Special Allowance | D25: {=VLOOKUP($B$7,_xlfn._xlws.FILTER('Employee data'!$A$1:$T$121,'Employee data'!$B$1:$B$121='Salary Slip'!$G$7),MATCH(A25,'Employee data'!$1:$1,0),0)} -> 4766.6667 | F25: TDS | H25: {=VLOOKUP($B$7,_xlfn._xlws.FILTER('Employee data'!$A$1:$T$121,'Employee data'!$B$1:$B$121='Salary Slip'!$G$7),MATCH(F25,'Employee data'!$1:$1,0),0)} -> 1390.99
A26: Other Earnings | D26: {=VLOOKUP($B$7,_xlfn._xlws.FILTER('Employee data'!$A$1:$T$121,'Employee data'!$B$1:$B$121='Salary Slip'!$G$7),MATCH(A26,'Employee data'!$1:$1,0),0)} -> 0 | F26: Other Deductions | H26: {=VLOOKUP($B$7,_xlfn._xlws.FILTER('Employee data'!$A$1:$T$121,'Employee data'!$B$1:$B$121='Salary Slip'!$G$7),MATCH(F26,'Employee data'!$1:$1,0),0)} -> 0
A27: GROSS EARNINGS | D27: {=VLOOKUP($B$7,_xlfn._xlws.FILTER('Employee data'!$A$1:$T$121,'Employee data'!$B$1:$B$121='Salary Slip'!$G$7),MATCH(A27,'Employee data'!$1:$1,0),0)} -> 46366.333 | F27: TOTAL DEDUCTIONS | H27: {=VLOOKUP($B$7,_xlfn._xlws.FILTER('Employee data'!$A$1:$T$121,'Employee data'!$B$1:$B$121='Salary Slip'!$G$7),MATCH(F27,'Employee data'!$1:$1,0),0)} -> 5786.7375
A29: NET SALARY PAYABLE | F29: {=VLOOKUP($B$7,_xlfn._xlws.FILTER('Employee data'!$A$1:$T$121,'Employee data'!$B$1:$B$121='Salary Slip'!$G$7),20,0)} -> 40579.596
A30: =LEFT(_xlfn.XLOOKUP(B7,'Employee Master Table'!A:A,'Employee Master Table'!C:C), FIND(" ", _xlfn.XLOOKUP(B7,'Employee Master Table'!A:A,'Employee Master Table'!C:C)) - 1) -> Rahul | F30: Vishwas
A32: Employee Signatory | F32: Authorized Signatory
F33: Stark Industries
