Workbook

Sheet Q1
A1: Product | B1: Jan | C1: Feb | D1: Mar | E1: Total | G1: Q1 | H1: Find total of sugare (DGET)
A2: Coffee | B2: 2000 | C2: 348 | D2: 60 | E2: 697 | H2: Product | I2: Total
A3: Candy | B3: 288 | C3: 145 | D3: 149 | E3: 582 | H3: Sugar | I3: =DGET(A1:E11,E1,H2:H3) -> 968
A4: Chocolate | B4: 299 | C4: 192 | D4: 288 | E4: 779
A5: Sugar | B5: 360 | C5: 219 | D5: 389 | E5: 968
A6: Milk Powder | B6: 250 | C6: 395 | D6: 261 | E6: 906
A7: Biscuit | B7: 47 | C7: 134 | D7: 121 | E7: 302
A8: Cold Drinks | B8: 396 | C8: 282 | D8: 141 | E8: 819
A9: Energy Drinks | B9: 291 | C9: 359 | D9: 167 | E9: 817
A10: Fruit Juice | B10: 243 | C10: 287 | D10: 375 | E10: 905
A11: Total | B11: 2463 | C11: 2361 | D11: 1951 | E11: 6775

Sheet Q2
A1: Product | B1: Jan | C1: Feb | D1: Mar | E1: Total
A2: Coffee | B2: 307 | C2: 196 | D2: 362 | E2: 865
A3: Candy | B3: 160 | C3: 178 | D3: 21 | E3: 359
A4: Chocolate | B4: 144 | C4: 139 | D4: 198 | E4: 481
A5: Sugar | B5: 289 | C5: 69 | D5: 139 | E5: 497
A6: Milk Powder | B6: 183 | C6: 244 | D6: 358 | E6: 785
A7: Biscuit | B7: 63 | C7: 276 | D7: 63 | E7: 402
A8: Cold Drinks | B8: 287 | C8: 197 | D8: 84 | E8: 568
A9: Energy Drinks | B9: 193 | C9: 177 | D9: 276 | E9: 646
A10: Fruit Juice | B10: 101 | C10: 380 | D10: 121 | E10: 602
A11: Total | B11: 1727 | C11: 1856 | D11: 1622 | E11: 5205

Sheet Q3
A1: Product | B1: Jan | C1: Feb | D1: Mar | E1: Total
A2: Coffee | B2: 228 | C2: 100 | D2: 80 | E2: =SUM(B2:D2) -> 408
A3: Candy | B3: 269 | C3: 309 | D3: 182 | E3: =SUM(B3:D3) -> 760
A4: Chocolate | B4: 276 | C4: 108 | D4: 204 | E4: =SUM(B4:D4) -> 588
A5: Sugar | B5: 307 | C5: 234 | D5: 175 | E5: =SUM(B5:D5) -> 716
A6: Milk Powder | B6: 221 | C6: 193 | D6: 198 | E6: =SUM(B6:D6) -> 612
A7: Biscuit | B7: 124 | C7: 63 | D7: 78 | E7: =SUM(B7:D7) -> 265
A8: Cold Drinks | B8: 104 | C8: 334 | D8: 246 | E8: =SUM(B8:D8) -> 684
A9: Energy Drinks | B9: 288 | C9: 107 | D9: 325 | E9: =SUM(B9:D9) -> 720
A10: Fruit Juice | B10: 218 | C10: 106 | D10: 215 | E10: =SUM(B10:D10) -> 539
A11: Total | B11: =SUM(B2:B10) -> 2035 | C11: =SUM(C2:C10) -> 1554 | D11: =SUM(D2:D10) -> 1703 | E11: =SUM(B11:D11) -> 5292

Sheet sum
B1: Jan | C1: Feb | D1: Mar | E1: Total
B2: ='Q1'!$B$2 -> 2000 | C2: ='Q1'!$C$2 -> 348 | D2: ='Q1'!$D$2 -> 60 | E2: ='Q1'!$E$2 -> 697
B3: ='Q2'!$B$2 -> 307 | C3: ='Q2'!$C$2 -> 196 | D3: ='Q2'!$D$2 -> 362 | E3: ='Q2'!$E$2 -> 865
B4: ='Q3'!$B$2 -> 228 | C4: ='Q3'!$C$2 -> 100 | D4: ='Q3'!$D$2 -> 80 | E4: ='Q3'!$E$2 -> 408
A5: Coffee | B5: =SUM(B2:B4) -> 2535 | C5: =SUM(C2:C4) -> 644 | D5: =SUM(D2:D4) -> 502 | E5: =SUM(E2:E4) -> 1970
B6: ='Q1'!$B$3 -> 288 | C6: ='Q1'!$C$3 -> 145 | D6: ='Q1'!$D$3 -> 149 | E6: ='Q1'!$E$3 -> 582
B7: ='Q2'!$B$3 -> 160 | C7: ='Q2'!$C$3 -> 178 | D7: ='Q2'!$D$3 -> 21 | E7: ='Q2'!$E$3 -> 359
B8: ='Q3'!$B$3 -> 269 | C8: ='Q3'!$C$3 -> 309 | D8: ='Q3'!$D$3 -> 182 | E8: ='Q3'!$E$3 -> 760
A9: Candy | B9: =SUM(B6:B8) -> 717 | C9: =SUM(C6:C8) -> 632 | D9: =SUM(D6:D8) -> 352 | E9: =SUM(E6:E8) -> 1701
B10: ='Q1'!$B$4 -> 299 | C10: ='Q1'!$C$4 -> 192 | D10: ='Q1'!$D$4 -> 288 | E10: ='Q1'!$E$4 -> 779
B11: ='Q2'!$B$4 -> 144 | C11: ='Q2'!$C$4 -> 139 | D11: ='Q2'!$D$4 -> 198 | E11: ='Q2'!$E$4 -> 481
B12: ='Q3'!$B$4 -> 276 | C12: ='Q3'!$C$4 -> 108 | D12: ='Q3'!$D$4 -> 204 | E12: ='Q3'!$E$4 -> 588
A13: Chocolate | B13: =SUM(B10:B12) -> 719 | C13: =SUM(C10:C12) -> 439 | D13: =SUM(D10:D12) -> 690 | E13: =SUM(E10:E12) -> 1848
B14: ='Q1'!$B$5 -> 360 | C14: ='Q1'!$C$5 -> 219 | D14: ='Q1'!$D$5 -> 389 | E14: ='Q1'!$E$5 -> 968
B15: ='Q2'!$B$5 -> 289 | C15: ='Q2'!$C$5 -> 69 | D15: ='Q2'!$D$5 -> 139 | E15: ='Q2'!$E$5 -> 497
B16: ='Q3'!$B$5 -> 307 | C16: ='Q3'!$C$5 -> 234 | D16: ='Q3'!$D$5 -> 175 | E16: ='Q3'!$E$5 -> 716
A17: Sugar | B17: =SUM(B14:B16) -> 956 | C17: =SUM(C14:C16) -> 522 | D17: =SUM(D14:D16) -> 703 | E17: =SUM(E14:E16) -> 2181
B18: ='Q1'!$B$6 -> 250 | C18: ='Q1'!$C$6 -> 395 | D18: ='Q1'!$D$6 -> 261 | E18: ='Q1'!$E$6 -> 906
B19: ='Q2'!$B$6 -> 183 | C19: ='Q2'!$C$6 -> 244 | D19: ='Q2'!$D$6 -> 358 | E19: ='Q2'!$E$6 -> 785
B20: ='Q3'!$B$6 -> 221 | C20: ='Q3'!$C$6 -> 193 | D20: ='Q3'!$D$6 -> 198 | E20: ='Q3'!$E$6 -> 612
A21: Milk Powder | B21: =SUM(B18:B20) -> 654 | C21: =SUM(C18:C20) -> 832 | D21: =SUM(D18:D20) -> 817 | E21: =SUM(E18:E20) -> 2303
B22: ='Q1'!$B$7 -> 47 | C22: ='Q1'!$C$7 -> 134 | D22: ='Q1'!$D$7 -> 121 | E22: ='Q1'!$E$7 -> 302
B23: ='Q2'!$B$7 -> 63 | C23: ='Q2'!$C$7 -> 276 | D23: ='Q2'!$D$7 -> 63 | E23: ='Q2'!$E$7 -> 402
B24: ='Q3'!$B$7 -> 124 | C24: ='Q3'!$C$7 -> 63 | D24: ='Q3'!$D$7 -> 78 | E24: ='Q3'!$E$7 -> 265
A25: Biscuit | B25: =SUM(B22:B24) -> 234 | C25: =SUM(C22:C24) -> 473 | D25: =SUM(D22:D24) -> 262 | E25: =SUM(E22:E24) -> 969
B26: ='Q1'!$B$8 -> 396 | C26: ='Q1'!$C$8 -> 282 | D26: ='Q1'!$D$8 -> 141 | E26: ='Q1'!$E$8 -> 819
B27: ='Q2'!$B$8 -> 287 | C27: ='Q2'!$C$8 -> 197 | D27: ='Q2'!$D$8 -> 84 | E27: ='Q2'!$E$8 -> 568
B28: ='Q3'!$B$8 -> 104 | C28: ='Q3'!$C$8 -> 334 | D28: ='Q3'!$D$8 -> 246 | E28: ='Q3'!$E$8 -> 684
A29: Cold Drinks | B29: =SUM(B26:B28) -> 787 | C29: =SUM(C26:C28) -> 813 | D29: =SUM(D26:D28) -> 471 | E29: =SUM(E26:E28) -> 2071
B30: ='Q1'!$B$9 -> 291 | C30: ='Q1'!$C$9 -> 359 | D30: ='Q1'!$D$9 -> 167 | E30: ='Q1'!$E$9 -> 817
B31: ='Q2'!$B$9 -> 193 | C31: ='Q2'!$C$9 -> 177 | D31: ='Q2'!$D$9 -> 276 | E31: ='Q2'!$E$9 -> 646
B32: ='Q3'!$B$9 -> 288 | C32: ='Q3'!$C$9 -> 107 | D32: ='Q3'!$D$9 -> 325 | E32: ='Q3'!$E$9 -> 720
A33: Energy Drinks | B33: =SUM(B30:B32) -> 772 | C33: =SUM(C30:C32) -> 643 | D33: =SUM(D30:D32) -> 768 | E33: =SUM(E30:E32) -> 2183
B34: ='Q1'!$B$10 -> 243 | C34: ='Q1'!$C$10 -> 287 | D34: ='Q1'!$D$10 -> 375 | E34: ='Q1'!$E$10 -> 905
B35: ='Q2'!$B$10 -> 101 | C35: ='Q2'!$C$10 -> 380 | D35: ='Q2'!$D$10 -> 121 | E35: ='Q2'!$E$10 -> 602
B36: ='Q3'!$B$10 -> 218 | C36: ='Q3'!$C$10 -> 106 | D36: ='Q3'!$D$10 -> 215 | E36: ='Q3'!$E$10 -> 539
A37: Fruit Juice | B37: =SUM(B34:B36) -> 562 | C37: =SUM(C34:C36) -> 773 | D37: =SUM(D34:D36) -> 711 | E37: =SUM(E34:E36) -> 2046
B38: ='Q1'!$B$11 -> 2463 | C38: ='Q1'!$C$11 -> 2361 | D38: ='Q1'!$D$11 -> 1951 | E38: ='Q1'!$E$11 -> 6775
B39: ='Q2'!$B$11 -> 1727 | C39: ='Q2'!$C$11 -> 1856 | D39: ='Q2'!$D$11 -> 1622 | E39: ='Q2'!$E$11 -> 5205
B40: ='Q3'!$B$11 -> 2035 | C40: ='Q3'!$C$11 -> 1554 | D40: ='Q3'!$D$11 -> 1703 | E40: ='Q3'!$E$11 -> 5292
...

Sheet max
B1: Jan | C1: Feb | D1: Mar | E1: Total
B2: ='Q1'!$B$2 -> 2000 | C2: ='Q1'!$C$2 -> 348 | D2: ='Q1'!$D$2 -> 60 | E2: ='Q1'!$E$2 -> 697
B3: ='Q2'!$B$2 -> 307 | C3: ='Q2'!$C$2 -> 196 | D3: ='Q2'!$D$2 -> 362 | E3: ='Q2'!$E$2 -> 865
B4: ='Q3'!$B$2 -> 228 | C4: ='Q3'!$C$2 -> 100 | D4: ='Q3'!$D$2 -> 80 | E4: ='Q3'!$E$2 -> 408
A5: Coffee | B5: =MAX(B2:B4) -> 2000 | C5: =MAX(C2:C4) -> 348 | D5: =MAX(D2:D4) -> 362 | E5: =MAX(E2:E4) -> 865
B6: ='Q1'!$B$3 -> 288 | C6: ='Q1'!$C$3 -> 145 | D6: ='Q1'!$D$3 -> 149 | E6: ='Q1'!$E$3 -> 582
B7: ='Q2'!$B$3 -> 160 | C7: ='Q2'!$C$3 -> 178 | D7: ='Q2'!$D$3 -> 21 | E7: ='Q2'!$E$3 -> 359
B8: ='Q3'!$B$3 -> 269 | C8: ='Q3'!$C$3 -> 309 | D8: ='Q3'!$D$3 -> 182 | E8: ='Q3'!$E$3 -> 760
A9: Candy | B9: =MAX(B6:B8) -> 288 | C9: =MAX(C6:C8) -> 309 | D9: =MAX(D6:D8) -> 182 | E9: =MAX(E6:E8) -> 760
B10: ='Q1'!$B$4 -> 299 | C10: ='Q1'!$C$4 -> 192 | D10: ='Q1'!$D$4 -> 288 | E10: ='Q1'!$E$4 -> 779
B11: ='Q2'!$B$4 -> 144 | C11: ='Q2'!$C$4 -> 139 | D11: ='Q2'!$D$4 -> 198 | E11: ='Q2'!$E$4 -> 481
B12: ='Q3'!$B$4 -> 276 | C12: ='Q3'!$C$4 -> 108 | D12: ='Q3'!$D$4 -> 204 | E12: ='Q3'!$E$4 -> 588
A13: Chocolate | B13: =MAX(B10:B12) -> 299 | C13: =MAX(C10:C12) -> 192 | D13: =MAX(D10:D12) -> 288 | E13: =MAX(E10:E12) -> 779
B14: ='Q1'!$B$5 -> 360 | C14: ='Q1'!$C$5 -> 219 | D14: ='Q1'!$D$5 -> 389 | E14: ='Q1'!$E$5 -> 968
B15: ='Q2'!$B$5 -> 289 | C15: ='Q2'!$C$5 -> 69 | D15: ='Q2'!$D$5 -> 139 | E15: ='Q2'!$E$5 -> 497
B16: ='Q3'!$B$5 -> 307 | C16: ='Q3'!$C$5 -> 234 | D16: ='Q3'!$D$5 -> 175 | E16: ='Q3'!$E$5 -> 716
A17: Sugar | B17: =MAX(B14:B16) -> 360 | C17: =MAX(C14:C16) -> 234 | D17: =MAX(D14:D16) -> 389 | E17: =MAX(E14:E16) -> 968
B18: ='Q1'!$B$6 -> 250 | C18: ='Q1'!$C$6 -> 395 | D18: ='Q1'!$D$6 -> 261 | E18: ='Q1'!$E$6 -> 906
B19: ='Q2'!$B$6 -> 183 | C19: ='Q2'!$C$6 -> 244 | D19: ='Q2'!$D$6 -> 358 | E19: ='Q2'!$E$6 -> 785
B20: ='Q3'!$B$6 -> 221 | C20: ='Q3'!$C$6 -> 193 | D20: ='Q3'!$D$6 -> 198 | E20: ='Q3'!$E$6 -> 612
A21: Milk Powder | B21: =MAX(B18:B20) -> 250 | C21: =MAX(C18:C20) -> 395 | D21: =MAX(D18:D20) -> 358 | E21: =MAX(E18:E20) -> 906
B22: ='Q1'!$B$7 -> 47 | C22: ='Q1'!$C$7 -> 134 | D22: ='Q1'!$D$7 -> 121 | E22: ='Q1'!$E$7 -> 302
B23: ='Q2'!$B$7 -> 63 | C23: ='Q2'!$C$7 -> 276 | D23: ='Q2'!$D$7 -> 63 | E23: ='Q2'!$E$7 -> 402
B24: ='Q3'!$B$7 -> 124 | C24: ='Q3'!$C$7 -> 63 | D24: ='Q3'!$D$7 -> 78 | E24: ='Q3'!$E$7 -> 265
A25: Biscuit | B25: =MAX(B22:B24) -> 124 | C25: =MAX(C22:C24) -> 276 | D25: =MAX(D22:D24) -> 121 | E25: =MAX(E22:E24) -> 402
B26: ='Q1'!$B$8 -> 396 | C26: ='Q1'!$C$8 -> 282 | D26: ='Q1'!$D$8 -> 141 | E26: ='Q1'!$E$8 -> 819
B27: ='Q2'!$B$8 -> 287 | C27: ='Q2'!$C$8 -> 197 | D27: ='Q2'!$D$8 -> 84 | E27: ='Q2'!$E$8 -> 568
B28: ='Q3'!$B$8 -> 104 | C28: ='Q3'!$C$8 -> 334 | D28: ='Q3'!$D$8 -> 246 | E28: ='Q3'!$E$8 -> 684
A29: Cold Drinks | B29: =MAX(B26:B28) -> 396 | C29: =MAX(C26:C28) -> 334 | D29: =MAX(D26:D28) -> 246 | E29: =MAX(E26:E28) -> 819
B30: ='Q1'!$B$9 -> 291 | C30: ='Q1'!$C$9 -> 359 | D30: ='Q1'!$D$9 -> 167 | E30: ='Q1'!$E$9 -> 817
B31: ='Q2'!$B$9 -> 193 | C31: ='Q2'!$C$9 -> 177 | D31: ='Q2'!$D$9 -> 276 | E31: ='Q2'!$E$9 -> 646
B32: ='Q3'!$B$9 -> 288 | C32: ='Q3'!$C$9 -> 107 | D32: ='Q3'!$D$9 -> 325 | E32: ='Q3'!$E$9 -> 720
A33: Energy Drinks | B33: =MAX(B30:B32) -> 291 | C33: =MAX(C30:C32) -> 359 | D33: =MAX(D30:D32) -> 325 | E33: =MAX(E30:E32) -> 817
B34: ='Q1'!$B$10 -> 243 | C34: ='Q1'!$C$10 -> 287 | D34: ='Q1'!$D$10 -> 375 | E34: ='Q1'!$E$10 -> 905
B35: ='Q2'!$B$10 -> 101 | C35: ='Q2'!$C$10 -> 380 | D35: ='Q2'!$D$10 -> 121 | E35: ='Q2'!$E$10 -> 602
B36: ='Q3'!$B$10 -> 218 | C36: ='Q3'!$C$10 -> 106 | D36: ='Q3'!$D$10 -> 215 | E36: ='Q3'!$E$10 -> 539
A37: Fruit Juice | B37: =MAX(B34:B36) -> 243 | C37: =MAX(C34:C36) -> 380 | D37: =MAX(D34:D36) -> 375 | E37: =MAX(E34:E36) -> 905
B38: ='Q1'!$B$11 -> 2463 | C38: ='Q1'!$C$11 -> 2361 | D38: ='Q1'!$D$11 -> 1951 | E38: ='Q1'!$E$11 -> 6775
B39: ='Q2'!$B$11 -> 1727 | C39: ='Q2'!$C$11 -> 1856 | D39: ='Q2'!$D$11 -> 1622 | E39: ='Q2'!$E$11 -> 5205
B40: ='Q3'!$B$11 -> 2035 | C40: ='Q3'!$C$11 -> 1554 | D40: ='Q3'!$D$11 -> 1703 | E40: ='Q3'!$E$11 -> 5292
...
